Workbook

Sheet Respuestas
A1: Marca temporal | B1: Nombre completo | C1: Número de documento | D1: Fecha de nacimiento | E1: Edad | F1: Sexo | G1: Estado civil | H1: Ciudad de residencia | I1: Teléfono | J1: Cargo | K1: Área | L1: Sede | M1: Antigüedad | N1: Tipo de contrato | O1: Profesión | P1: ¿Estudiando? | Q1: ¿Qué estudia? | R1: ¿Tiene hijos? | S1: Número de hijos | T1: Hijo 1 - Fecha de nacimiento | U1: Hijo 1 - Edad | V1: Hijo 1 - Sexo | W1: Hijo 1 - ¿Vive con usted? | X1: Hijo 1 - Dirección donde vive | Y1: Hijo 2 - Fecha de nacimiento | Z1: Hijo 2 - Edad | AA1: Hijo 2 - Sexo | AB1: Hijo 2 - ¿Vive con usted? | AC1: Hijo 2 - Dirección donde vive | AD1: Hijo 3 - Fecha de nacimiento | AE1: Hijo 3 - Edad | AF1: Hijo 3 - Sexo | AG1: Hijo 3 - ¿Vive con usted? | AH1: Hijo 3 - Dirección donde vive | AI1: Hijo 4 - Fecha de nacimiento | AJ1: Hijo 4 - Edad | AK1: Hijo 4 - Sexo | AL1: Hijo 4 - ¿Vive con usted? | AM1: Hijo 4 - Dirección donde vive | AN1: Hijo 5 - Fecha de nacimiento | AO1: Hijo 5 - Edad | AP1: Hijo 5 - Sexo | AQ1: Hijo 5 - ¿Vive con usted? | AR1: Hijo 5 - Dirección donde vive | AS1: Hijo 6 - Fecha de nacimiento | AT1: Hijo 6 - Edad | AU1: Hijo 6 - Sexo | AV1: Hijo 6 - ¿Vive con usted? | AW1: Hijo 6 - Dirección donde vive
A2: 46295.656 | B2: JINA ESPERANZA MOLINA PULIDO | C2: 1094932380 | D2: 33981 | E2: 33 | F2: Mujer | G2: Soltero(a) | H2: ARMENIA | J2: PROFESIONAL DE CULTURA | K2: C.E.C | L2: SEDE ADMINISTRATIVA ARMENIA | M2: Entre 6 meses y 1 año | O2: PSICOLOGA | P2: No | R2: No
A3: 46297.712 | B3: Laura Valentina Jaramillo Garcia | C3: 1192801294 | D3: 37068 | E3: 25 | F3: Mujer | G3: Unión libre | H3: Manizales | J3: Higiénista oral | K3: Asistencial | L3: Manizales | M3: Entre 6 meses y 1 año | O3: Higiénista oral | P3: No | R3: Sí | S3: 1 | T3: 44728 | U3: 4 | V3: Hombre | W3: Sí | X3: Manizales
A4: 46297.713 | B4: Olga Otero Hurtado | C4: 1107104320 | D4: 35395 | E4: 29 | F4: Mujer | G4: Soltero(a) | H4: Silvia | J4: Tecnóloga en mamografias | K4: Asistencial | L4: Unidad móvil felicidad | M4: Entre 6 meses y 1 año | O4: Tecnóloga en radiología e imágenes diagnósticas | P4: No | R4: No
A5: 46297.713 | B5: Ana María Alegria Monroy | C5: 1002876732 | D5: 36687 | E5: 26 | F5: Mujer | G5: Unión libre | H5: Coconuco | J5: Auxiliar de Agendamiento | K5: Agendamiento | L5: Popayán | M5: Entre 6 meses y 1 año | O5: Tecnóloga en gestión empresarial | P5: No | R5: No
A6: 46297.714 | B6: Angie Natalia Vidal Arango | C6: 1097720813 | D6: 38293 | E6: 21 | F6: Mujer | G6: Unión libre | H6: Montenegro | J6: Auxiliar toma de muestras | K6: Asistencial | L6: Unidad movil felicidad | M6: Menos de 6 meses | O6: Auxiliar de enfermería | P6: No | R6: No
A7: 46297.715 | B7: Liseth Natalia Rodríguez cortes | C7: 1016079493 | D7: 34955 | E7: 31 | F7: Mujer | G7: Soltero(a) | H7: Fusagasugá | J7: Tecnologa en imágenes diagnósticas | K7: Radiología | L7: Unidad móvil compsion | M7: Menos de 6 meses | O7: Tecnologa en radiología e imágenes diagnósticas | P7: No | R7: Sí | S7: 2 | T7: 42313 | U7: 10 | V7: Hombre | W7: Sí | X7: Fusagasugá | Y7: 43762 | Z7: 6 | AA7: Mujer | AB7: Sí | AC7: Fusagasugá
A8: 46297.724 | B8: Melissa Paola Chica Beleño | C8: 1102812141 | D8: 32094 | E8: 38 | F8: Mujer | G8: Casado(a) | H8: Armenia | J8: Directora CADI | K8: CADI- Centro de Agendamiento y Demanda Inducida | L8: Sede Administrativa | M8: Más de 5 años | O8: Trabajadora Social | P8: No | R8: Sí | S8: 1 | T8: 43520 | U8: 7 | V8: Hombre | W8: Sí | X8: Armenia
A9: 46297.724 | B9: Jhon Sebastián Patiño Rueda | C9: 1010217 | D9: 34593 | E9: 32 | F9: Hombre | G9: Unión libre | H9: BOGOTA, D.C. | J9: Gerente Médico | K9: Gerencia General | L9: Bogotá | M9: Entre 1 y 3 años | O9: Médico, Magister en Salud Pública y Magister en Políticas Públicas | P9: No | R9: No
A10: 46297.725 | B10: Alejandra ojeda | C10: 1061747471 | D10: 33728 | E10: 34 | F10: Mujer | G10: Unión libre | H10: Popayan | J10: Auxiliar de toma de muestra | K10: Extramural | L10: Felicidad | M10: Entre 6 meses y 1 año | O10: Auxiliar de enfermería | P10: Sí | Q10: Pscicolgia | R10: Sí | S10: 1 | T10: 43977 | U10: 6 | V10: Hombre | W10: Sí | X10: Popayan
A11: 46297.726 | B11: Diego Armando Botina Botina | C11: 1004232427 | D11: 36604 | E11: 26 | F11: Hombre | G11: Soltero(a) | H11: Pasto | J11: Auxiliar operativo | K11: Asistencial | L11: Unidades moviles | M11: Entre 6 meses y 1 año | O11: Tecnólogo en promoción de la salud | P11: No | R11: No
A12: 46297.74 | B12: Laura lucia Villegas Naranjo | C12: 1094955300 | D12: 35138 | E12: 30 | F12: Mujer | G12: Soltero(a) | H12: Armenia | J12: Arquitecta | K12: Calidad | L12: Armenia | M12: Entre 6 meses y 1 año | O12: Arquitectura | P12: No | R12: Sí | S12: 1 | T12: 45908 | U12: 1 | V12: Hombre | W12: Sí | X12: Armenia
A13: 46297.749 | B13: JAIR DUCARDO LOPEZ ,UÑOZ | C13: 10301042 | D13: 30655 | E13: 42 | F13: Hombre | G13: Soltero(a) | H13: POPAYÁN | J13: AUXILIAR OPERATIVO | K13: ADMINISTRATIVO | L13: UNIDAD MOVIL | M13: Entre 6 meses y 1 año | O13: TECNICO EN SISTEMAS, TECNICO EN ADMINISTRACION DOCUMENTAL Y AUXILIAR ENFERMERO | P13: Sí | Q13: TECNOLOGO EN IMAGENES DIAGNOSTICAS Y RADIOLOGIA | R13: Sí | S13: 1 | T13: 42227 | U13: 11 | V13: Hombre | W13: No | X13: POPAYAN
A14: 46297.759 | B14: Leidy juliana Ortiz villa | C14: 1053788236 | D14: 32256 | E14: 38 | F14: Mujer | G14: Separado(a) | H14: Manizales | J14: Auxiliar enfermería | K14: Unidades móviles | L14: Armenia | M14: Entre 1 y 3 años | O14: Auxiliar enfermería | P14: No | R14: Sí | S14: 2 | T14: 38927 | U14: 20 | V14: Mujer | W14: Sí | X14: Manizales | Y14: 40664 | Z14: 15 | AA14: Hombre | AB14: Sí | AC14: Manizales
A15: 46297.759 | B15: Yuli Andrea Joaquí Romero | C15: 1061747303 | D15: 33651 | E15: 34 | F15: Mujer | G15: Soltero(a) | H15: Popayan | J15: Aux de poct | K15: Toma de muestras | L15: Compasión | M15: Entre 6 meses y 1 año | O15: Toma de muestras | P15: No | R15: Sí | S15: 1 | T15: 44679 | U15: 4 | V15: Mujer | W15: Sí | X15: Popayan
A16: 46297.761 | B16: Carlos Andrés Caraballo Airiarte | C16: 92535503 | D16: 29053 | E16: 47 | F16: Hombre | G16: Casado(a) | H16: Popayán | J16: Auxiliar administrativo Aprendiz sena | K16: Administrativa | L16: Sede Popayán | M16: Menos de 6 meses | O16: Tecnólogo administrativo en Salud | P16: Sí | Q16: Administración en Salud | R16: Sí | S16: 4 | T16: 36837 | U16: 25 | V16: Mujer | W16: No | X16: Barranquilla | Y16: 37498 | Z16: 24 | AA16: Mujer | AB16: No | AC16: Barranquilla | AD16: 40799 | AE16: 15 | AF16: Hombre | AG16: No | AH16: Barranquilla | AI16: 41420 | AJ16: 13 | AK16: Hombre | AL16: No | AM16: Barranquilla
A17: 46297.8 | B17: MELISSA VIRGINIA VASQUEZ CERON | C17: 34318000 | D17: 30134 | E17: 44 | F17: Mujer | G17: Casado(a) | H17: POPAYAN | J17: PSICOLOGIA | K17: ASISTENCIAL | L17: POPAYAN | M17: Entre 6 meses y 1 año | O17: PSICOLOGIA | P17: Sí | Q17: DIPLOMADO | R17: Sí | S17: 2 | T17: 39024 | U17: 19 | V17: Mujer | W17: Sí | X17: POPAYAN | Y17: 44066 | Z17: 6 | AA17: Hombre | AB17: Sí | AC17: POPAYAN
A18: 46297.801 | B18: EVA AIDES PARALES RAMIREZ | C18: 1116864845 | D18: 34117 | E18: 33 | F18: Mujer | G18: Casado(a) | H18: MALAGA SANTANDER | J18: AUX DE ENFERMERIA | K18: AGENDAMIENTO | L18: DESDE CASA | M18: Menos de 6 meses | O18: AUX DE ENFERMERIA | P18: No | R18: Sí | S18: 3 | T18: 40694 | U18: 15 | V18: Hombre | W18: Sí | X18: MALAGA SANTANDER | Y18: 43965 | Z18: 6 | AA18: Hombre | AB18: Sí | AC18: MALAGA SANTANDER | AD18: 44514 | AE18: 4 | AF18: Hombre | AG18: Sí | AH18: MALAGA SANTANDER
A19: 46297.815 | B19: Edil Fernando Dorado | C19: 10548185 | D19: 24031 | E19: 60 | F19: Hombre | G19: Casado(a) | H19: Popayán | J19: Medico general | K19: Consulta externa | L19: Cede el recuerdo Popayán | M19: Entre 6 meses y 1 año | O19: Medico general | P19: No | R19: Sí | S19: 2 | T19: 32942 | U19: 36 | V19: Mujer | W19: No | X19: Popayán | Y19: 35051 | Z19: 30 | AA19: Mujer | AB19: No | AC19: Popayán
A20: 46297.819 | B20: LUCILA ANDREA JARAMILLO JARAMILLO | C20: 1124849363 | D20: 31566 | E20: 40 | F20: Mujer | G20: Casado(a) | H20: CHINCHINA CALDAS | J20: AUXILIAR DE ENFERMERIA | K20: AGENDAMIENTO Y DEMANDA INDUCIDA | L20: DIRRECION DE AGENDAMIENTO Y DEMANDA INDUCIDA | M20: Menos de 6 meses | O20: TECNICO EN ENFERMRIA | P20: Sí | Q20: COMPLEMENTARIO HUMANIZACION, ATENCION A VICTIMAS DEL CONFICTO ARMADO, ATENCION A VICTIMAS DEDE VIOLENCIA SEXUAL,FACTURACION SERVICIOS DE SALUD, ATENCION AL RECIEN NACIDO | R20: Sí | S20: 2 | T20: 37716 | U20: 23 | V20: Mujer | W20: No | X20: CALI | Y20: 40389 | Z20: 16 | AA20: Hombre | AB20: Sí | AC20: CHINCHINA CALDAS
A21: 46297.83 | B21: CRISTIAN CAMILO ARCILA FRANCO | C21: 1017234295 | D21: 34944 | E21: 31 | F21: Mujer | G21: Soltero(a) | H21: ARMENIA | J21: INGENIERO AMBIENTAL | K21: CALIDAD | L21: NACIONAL | M21: Entre 6 meses y 1 año | O21: INGENIERO AMBIENTAL | P21: No | R21: No
A22: 46297.831 | B22: MARIA DANIELA ESTRADA TOBON | C22: 1094957933 | D22: 35305 | E22: 30 | F22: Mujer | G22: Soltero(a) | H22: ARMENIA | J22: COORDINADORA NACIONAL DE OPERACIONES | K22: OPERACIONES EXTRAMURALES | L22: NACIONAL | M22: Entre 1 y 3 años | O22: ENFERMERA PROFESIONAL | P22: No | R22: No
A23: 46298.273 | B23: LAURA CRISTINA GARCÍA QUINTERO | C23: 1053841351 | D23: 34785 | E23: 31 | F23: Mujer | G23: Soltero(a) | H23: Manizales | J23: Auxiliar operativo | K23: Extramuralidad | L23: Um amor | M23: Entre 1 y 3 años | O23: Técnica administración en salud | P23: No | R23: No
A24: 46298.286 | B24: danna lizeth zapata cifuentes | C24: 1055478699 | D24: 39567 | E24: 18 | F24: Mujer | G24: Soltero(a) | H24: MANIZALES | J24: prácticamente técnico asistente administrativa | K24: administración | L24: MANIZALES | M24: Menos de 6 meses | O24: técnico en asistencia administrativa | P24: Sí | Q24: tecnólogo en gestión administrativa | R24: No
A25: 46298.291 | B25: Maria Fernanda Mejia Henao | C25: 1053827149 | D25: 34129 | E25: 33 | F25: Mujer | G25: Casado(a) | H25: Manizales | J25: Lider sede Manizales | K25: Administrativa | L25: Manizales | M25: Más de 5 años | O25: Administración en Salud | P25: Sí | Q25: Administración en Salud | R25: Sí | S25: 1 | T25: 42813 | U25: 9 | V25: Hombre | W25: Sí | X25: Manizales
A26: 46298.308 | B26: VIVIANA ECHEVERRI ROJAS | C26: 1053818618 | D26: 33743 | E26: 34 | F26: Mujer | G26: Soltero(a) | H26: MANIZALES | J26: AUX FACTURACION | K26: ADMON- LINEA DE FRENTE | L26: MANIZALES | M26: Entre 3 y 5 años | O26: AUX ADMINISTRATIVO EN SALUD | P26: No | R26: No
A27: 46298.319 | B27: ESTEFANY DUQUE GALVIS | C27: 1053825977 | D27: 34072 | E27: 33 | F27: Mujer | G27: Casado(a) | H27: MANIZALES | J27: ODONTÓLOGA GENERAL | K27: ODONTOLOGÍA | L27: MANIZALES | M27: Entre 1 y 3 años | O27: ODONTÓLOGA | P27: No | R27: No
A28: 46298.324 | B28: Valeria Villota lozano | C28: 1233190229 | D28: 35705 | E28: 29 | F28: Mujer | G28: Soltero(a) | H28: Manizales | J28: Médico general | K28: Consulta externa | L28: Sede Manizales | M28: Menos de 6 meses | O28: Médico | P28: Sí | Q28: Diplomado | R28: No
A29: 46298.325 | B29: Yustin Estefania Aguirre Gaviria | C29: 1053822718 | D29: 33914 | E29: 33 | F29: Mujer | G29: Soltero(a) | H29: Manizales | J29: Auxiliar de agendamiento | K29: Administrativo | L29: Manizales | M29: Más de 5 años | O29: Auxiliar de enfermería | P29: No | R29: Sí | S29: 1 | T29: 42258 | U29: 11 | V29: Mujer | W29: Sí | X29: Manizales
A30: 46298.328 | B30: ENITH YOVANA RAMIREZ MUÑOZ | C30: 34315686 | D30: 29840 | E30: 45 | F30: Mujer | G30: Separado(a) | H30: POPAYAN | J30: AXULIAR DE FACTURACION | K30: FACTURACION | L30: SEDE POPAYAN | M30: Entre 6 meses y 1 año | O30: AUXILIAR DE FACTURACION | P30: No | R30: Sí | S30: 1 | T30: 37737 | U30: 23 | V30: Hombre | W30: Sí | X30: POPAYAN
A31: 46298.336 | B31: Sandra Milena Cifuentes | C31: 25102646 | D31: 28418 | E31: 48 | F31: Mujer | G31: Unión libre | H31: Manizales | J31: Auxiliar servicios generales | K31: Administrativo | L31: Sede Manizales | M31: Entre 1 y 3 años | O31: Servicios generales | P31: No | R31: Sí | S31: 1 | T31: 36211 | U31: 27 | V31: Hombre | W31: Sí | X31: Manizales
A32: 46298.336 | B32: Juan David Ortiz Sepulveda | C32: 1116268200 | D32: 34903 | E32: 31 | F32: Hombre | G32: Soltero(a) | H32: Manizales | J32: Nutricionista Dietista | K32: Consulta externa | L32: Manizales | M32: Entre 6 meses y 1 año | O32: Nutricionista | P32: No | R32: No
A33: 46298.35 | B33: María José Salazar Martinez | C33: 1059208233 | D33: 38626 | E33: 21 | F33: Mujer | G33: Soltero(a) | H33: Manizales | J33: Auxiliar de facturación | K33: Consulta externa | L33: Manizales | M33: Menos de 6 meses | O33: Auxiliar administrativa | P33: No | R33: Sí | S33: 1 | T33: 45822 | U33: 1 | V33: Hombre | W33: Sí | X33: Manizales
A34: 46298.355 | B34: Natalia Maritza Hernandez Cabrera | C34: 1006848706 | D34: 36684 | E34: 26 | F34: Mujer | G34: Soltero(a) | H34: Orito, Putumayo | J34: Auxiliar toma de muestras | K34: Unidad móvil | L34: Unidad móvil compasión | M34: Entre 1 y 3 años | O34: Auxiliar de enfermería | P34: No | R34: No
A35: 46298.361 | B35: Yaleidy Maritza Quiñones Daza | C35: 1058967613 | D35: 32575 | E35: 37 | F35: Mujer | G35: Soltero(a) | H35: popayan | J35: Higienista Oral | K35: Odontologia | L35: Sede Popayan | M35: Entre 1 y 3 años | O35: Higienista Oral | P35: No | R35: No
A36: 46298.363 | B36: Jesica Gallego Toro | C36: 1053796452 | D36: 32700 | E36: 37 | F36: Mujer | G36: Soltero(a) | H36: Manizales | J36: Aux SIAU | K36: Administrativa | L36: Manizales | M36: Entre 1 y 3 años | O36: Higienista oral | P36: Sí | Q36: Técnico en auxiliar administrativo en salud | R36: No
A37: 46298.368 | B37: Natalia Andrea Muñoz Garcia | C37: 1004798607 | D37: 36546 | E37: 26 | F37: Mujer | G37: Soltero(a) | H37: Armenia | J37: Auxiliar de agendamiento | K37: Agendamiento | L37: Desde casa | M37: Entre 6 meses y 1 año | O37: Auxiliar de enfermeria | P37: No | R37: Sí | S37: 1 | T37: 45530 | U37: 2 | V37: Hombre | W37: Sí | X37: Armenia
A38: 46298.369 | B38: Angela Yolima Guamanga Samboni | C38: 34316697 | D38: 29981 | E38: 44 | F38: Mujer | G38: Soltero(a) | H38: Popayan - Cauca | J38: Tecnica de imagenes Diagnosticas Unidad Movil | K38: Area asistencial Unidad Movil | L38: Unidad Movil Amor | M38: Entre 1 y 3 años | O38: Tecnica de imagenes Diagnosticas | P38: Sí | Q38: Tecnologia en Radiologia e Imagens Diagnosticas | R38: Sí | S38: 2 | T38: 38819 | U38: 20 | V38: Mujer | W38: Sí | X38: Popayan | Y38: 43610 | Z38: 7 | AA38: Hombre | AB38: Sí | AC38: Popayan
A39: 46298.41 | B39: Yudy Lorena Giraldo Alfonso | C39: 24339622 | D39: 31316 | E39: 41 | F39: Mujer | G39: Casado(a) | H39: Manizales | J39: Pediatra | K39: Consulta externa | L39: Manizales | M39: Menos de 6 meses | O39: Pediatra | P39: No | R39: No
A40: 46298.44 | B40: Kevin David Cañizales Acevedo | C40: 1115091205 | D40: 35848 | E40: 28 | F40: Hombre | G40: Soltero(a) | H40: Manizales | J40: Médico general | K40: Consulta externa | L40: Sede manizales | M40: Menos de 6 meses | O40: Médico general | P40: No | R40: No
...

Sheet 4-11_anos
A1: # | B1: Nombre del empleado | C1: Documento | D1: telefono | E1: Ciudad residencia | F1: Hijo | G1: Edad | H1: Sexo | I1: ¿Vive con usted? | J1: Ciudad donde vive | K1: DIRECCION
A2: 1 | B2: Laura Valentina Jaramillo Garcia | C2: 1192801294 | D2: {=_xlfn.XLOOKUP(C2,bd_colaboradores!A:A,bd_colaboradores!H:H)} | E2: Manizales | F2: Hijo 1 | G2: 4 | H2: Hombre | I2: Sí | J2: Manizales | K2: {=_xlfn.XLOOKUP(C2,bd_colaboradores!A:A,bd_colaboradores!I:I)}
A3: 2 | B3: Melissa Paola Chica Beleño | C3: 1102812141 | D3: {=_xlfn.XLOOKUP(C3,bd_colaboradores!A:A,bd_colaboradores!H:H)} | E3: Armenia | F3: Hijo 1 | G3: 7 | H3: Hombre | I3: Sí | J3: Armenia | K3: {=_xlfn.XLOOKUP(C3,bd_colaboradores!A:A,bd_colaboradores!I:I)}
A4: 3 | B4: Alejandra Ojeda | C4: 1061747471 | D4: {=_xlfn.XLOOKUP(C4,bd_colaboradores!A:A,bd_colaboradores!H:H)} | E4: Popayán | F4: Hijo 1 | G4: 6 | H4: Hombre | I4: Sí | J4: Popayán | K4: {=_xlfn.XLOOKUP(C4,bd_colaboradores!A:A,bd_colaboradores!I:I)}
A5: 4 | B5: Jair Ducardo Lopez Muñoz | C5: 10301042 | D5: {=_xlfn.XLOOKUP(C5,bd_colaboradores!A:A,bd_colaboradores!H:H)} | E5: Popayán | F5: Hijo 1 | G5: 11 | H5: Hombre | I5: No | J5: Popayán | K5: {=_xlfn.XLOOKUP(C5,bd_colaboradores!A:A,bd_colaboradores!I:I)}
A6: 5 | B6: Yuli Andrea Joaquí Romero | C6: 1061747303 | D6: {=_xlfn.XLOOKUP(C6,bd_colaboradores!A:A,bd_colaboradores!H:H)} | E6: Popayán | F6: Hijo 1 | G6: 4 | H6: Mujer | I6: Sí | J6: Popayán | K6: {=_xlfn.XLOOKUP(C6,bd_colaboradores!A:A,bd_colaboradores!I:I)}
A7: 6 | B7: Melissa Virginia Vasquez Ceron | C7: 34318000 | D7: {=_xlfn.XLOOKUP(C7,bd_colaboradores!A:A,bd_colaboradores!H:H)} | E7: Popayán | F7: Hijo 2 | G7: 6 | H7: Hombre | I7: Sí | J7: Popayán | K7: {=_xlfn.XLOOKUP(C7,bd_colaboradores!A:A,bd_colaboradores!I:I)}
A8: 7 | B8: Eva Aides Parales Ramirez | C8: 1116864845 | D8: {=_xlfn.XLOOKUP(C8,bd_colaboradores!A:A,bd_colaboradores!H:H)} | E8: Málaga (Santander) | F8: Hijo 2 | G8: 6 | H8: Hombre | I8: Sí | J8: Málaga Santander | K8: {=_xlfn.XLOOKUP(C8,bd_colaboradores!A:A,bd_colaboradores!I:I)}
A9: 8 | B9: Eva Aides Parales Ramirez | C9: 1116864845 | D9: {=_xlfn.XLOOKUP(C9,bd_colaboradores!A:A,bd_colaboradores!H:H)} | E9: Málaga (Santander) | F9: Hijo 3 | G9: 4 | H9: Hombre | I9: Sí | J9: Málaga Santander | K9: {=_xlfn.XLOOKUP(C9,bd_colaboradores!A:A,bd_colaboradores!I:I)}
A10: 9 | B10: Ángela Yolima Guamanga Samboni | C10: 34316697 | D10: {=_xlfn.XLOOKUP(C10,bd_colaboradores!A:A,bd_colaboradores!H:H)} | E10: Popayán | F10: Hijo 2 | G10: 7 | H10: Hombre | I10: Sí | J10: Popayán | K10: {=_xlfn.XLOOKUP(C10,bd_colaboradores!A:A,bd_colaboradores!I:I)}
A11: 10 | B11: Tiana Yamary Guerra Cadena | C11: 1053843916 | D11: {=_xlfn.XLOOKUP(C11,bd_colaboradores!A:A,bd_colaboradores!H:H)} | E11: Armenia | F11: Hijo 1 | G11: 4 | H11: Mujer | I11: Sí | J11: Armenia | K11: {=_xlfn.XLOOKUP(C11,bd_colaboradores!A:A,bd_colaboradores!I:I)}
A12: 11 | B12: Anyela Amparo Bermudez Quintana | C12: 1059606638 | D12: {=_xlfn.XLOOKUP(C12,bd_colaboradores!A:A,bd_colaboradores!H:H)} | E12: Morales (Cauca) | F12: Hijo 1 | G12: 6 | H12: Mujer | I12: Sí | J12: Morales Cauca | K12: {=_xlfn.XLOOKUP(C12,bd_colaboradores!A:A,bd_colaboradores!I:I)}
A13: 12 | B13: María Fernanda Durán Jaimes | C13: 1012444992 | D13: {=_xlfn.XLOOKUP(C13,bd_colaboradores!A:A,bd_colaboradores!H:H)} | E13: Armenia | F13: Hijo 1 | G13: 6 | H13: Hombre | I13: Sí | J13: Armenia | K13: {=_xlfn.XLOOKUP(C13,bd_colaboradores!A:A,bd_colaboradores!I:I)}
... A25: 24 | B25: Yustin Estefania Aguirre Gaviria | C25: 1053822718 | D25: {=_xlfn.XLOOKUP(C25,bd_colaboradores!A:A,bd_colaboradores!H:H)} | E25: Manizales | F25: Hijo 1 | G25: 11 | H25: Mujer | I25: Sí | J25: Manizales | K25: {=_xlfn.XLOOKUP(C25,bd_colaboradores!A:A,bd_colaboradores!I:I)}
A26: 25 | B26: Katerine Rosero Estrada | C26: 1061699732 | D26: 3215197275 | E26: Popayán | F26: Hijo 1 | G26: 10 | H26: Mujer | I26: Sí
A27: 26 | B27: Gerson Oved Reyes Manzano | C27: 1061714835 | D27: 3147722474 | E27: Popayán | F27: Hijo 1 | G27: 6 | H27: Hombre | I27: Sí
A28: 27 | B28: Susan Gomez Hernandez | C28: 34326410 | D28: 3182573837 | E28: Popayán | F28: Hijo 1 | G28: 11 | H28: Mujer | I28: Sí

Sheet bd_colaboradores
A1: CEDULA | B1: GENERO | C1: Columna 3 | D1: CARGO | E1: CORREO CORPORATIVO | F1: MACROPROCESO | G1: CORREO JEFE DIRECTO | H1: CELULAR | I1: DIRECCION | J1: CORREO PERSONAL | K1: JEFE DIRECTO | L1: CIUDAD DE RESIDENCIA | M1: FECHA NACIMIENTO | N1: FECHA EXPEDICION CEDULA | O1: CIUDAD EXPEDICION | P1: RH | Q1: ESTADO CIVIL | R1: HIJOS | S1: CUANTOS | T1: FECHA DE INGRESO | U1: Columna 7 | V1: ANTIGUEDAD | W1: Columna 23 | X1: Columna 10 | Y1: FUNCION | Z1: EMPRESA | AA1: CIUDAD DE LABORES | AB1: SEDE | AC1: TIPO CONTRATO | AD1: ESTADO | AE1: FOTO | AF1: Column 32 | AG1: Column 33 | AH1: Column 34 | AI1: Column 35 | AJ1: Column 36 | AK1: Column 37 | AL1: Column 38 | AM1: Column 39 | AN1: Column 40 | AO1: Column 41 | AP1: Column 42 | AQ1: Column 43 | AR1: Column 44 | AS1: Column 45 | AT1: Column 46 | AU1: Column 47 | AV1: Column 48 | AW1: Column 49 | AX1: Column 50 | AY1: Column 51 | AZ1: Column 52 | BA1: Column 53 | BB1: Column 54 | BC1: Column 55 | BD1: Column 56 | BE1: Column 57 | BF1: Column 58 | BG1: Column 59 | BH1: Column 60 | BI1: Column 61 | BJ1: Column 62 | BK1: Column 63 | BL1: Column 64 | BM1: Column 65 | BN1: Column 66 | BO1: Column 67 | BP1: Column 68 | BQ1: Column 69 | BR1: Column 70
A2: 79886896 | B2: M | C2: OSCAR ADRIAN VIVAS RAMIREZ | D2: GERENTE GENERAL | E2: oscar.vivas@saludhorisoes.org | F2: GERENCIA | G2: oscar.vivas@saludhorisoes.org | H2: 3147927981 | I2: CARRERA 17 # 56 -42 | J2: fernandovivasramire@hotmail.com | K2: PAOLA ANDRADE | L2: ARMENIA | M2: 28525 | N2: 35118 | O2: BOGOTA | P2: A+ | Q2: CASADO | R2: SI | S2: 3 | T2: 42842 | U2: 42826 | V2: 9.49 | W2: SIN DATO | Y2: ADMINISTRATIVA | Z2: SALUD HORISOES | AA2: ARMENIA | AB2: NACIONAL | AC2: INDEFINIDO | AD2: ACTIVO
A3: 52695133 | B3: F | C3: PAULA ANDREA VIVAS RAMIREZ | D3: PROFESIONAL ADMINISTRATIVA | E3: paula.vivas@saludhorisoes.org | F3: RECURSOS FISICOS | G3: dellanir.naizir@saludhorisoes.org | H3: 3013777111 | I3: CARRERA 17 # 48N 18 | J3: paula.vivas@ipshorisoes.org | K3: DELLANIR NAIZIR | L3: ARMENIA | M3: 29041 | N3: 35826 | O3: BOGOTA | P3: O+ | Q3: SOLTERO | R3: SI | S3: 2 | T3: 42887 | U3: 42887 | V3: 9.37 | W3: SIN DATO | Y3: ADMINISTRATIVA | Z3: SALUD HORISOES | AA3: ARMENIA | AB3: NACIONAL | AC3: INDEFINIDO | AD3: ACTIVO
A4: 1042436048 | B4: F | C4: MONICA INES BARCASNEGRAS VILLALOBOS | D4: GERENCIA DE PRESTACION DE SERIVICIOS | E4: monica.barcasnegras@saludhorisoes.org | F4: GERENCIA | G4: oscar.vivas@saludhorisoes.org | H4: 3162974847 | I4: CARRERA 36 # 17 - 122 BARRIO LA UNION | J4: monik9008@hotmail.com | K4: OSCAR VIVAS | L4: BARRANQUILLA | M4: 33215 | N4: 39822 | O4: SOLEDAD | P4: O+ | Q4: SOLTERO | R4: NO | S4: 0 | T4: 43070 | U4: 43070 | V4: 8.87 | W4: SIN DATO | Y4: OPERATIVO | Z4: SALUD HORISOES | AA4: ARMENIA | AB4: NACIONAL | AC4: INDEFINIDO | AD4: ACTIVO
A5: 1061762085 | B5: F | C5: MARIA ALEJANDRA FAJARDO QUINTERO | D5: PROFESIONAL CONTABLE | E5: maria.fajardo@saludhorisoes.org | F5: RECURSOS FINANCIEROS | G5: andres.suarez@saludhorisoes.org | H5: 3147699999 | I5: CARRERA 42 A #1 A 56 MARIA OCCIDENTE | J5: maria.fajardo@ipshorisoes.org | K5: ANA MARIA HINCAPIE | L5: POPAYAN | M5: 34205 | N5: 40795 | O5: POPAYAN | P5: O+ | Q5: SOLTERO | R5: NO | S5: 0 | T5: 43192 | U5: 43191 | V5: 8.53 | W5: SIN DATO | Y5: ADMINISTRATIVA | Z5: SALUD HORISOES | AA5: POPAYAN | AB5: NACIONAL | AC5: INDEFINIDO | AD5: ACTIVO | AE5: MARIA ALEJANDRA FAJARDO QUINTERO
A6: 45689747 | B6: F | C6: LISA MARIA CASTAÑO PAVA | D6: COORDINACION DE SEDE | E6: lisa.castano@saludhorisoes.org | F6: DIRECCION SOCIOSANITARIA | G6: monica.barcasnegras@saludhorisoes.org | H6: 3154108380 | I6: CALLE 9N #10 - 35 SANTA CLARA | J6: lcastanopava@hotmail.com | K6: MONICA BARCASNEGRAS | L6: POPAYAN | M6: 28468 | N6: 35353 | O6: CARTAGENA | P6: AB+ | Q6: CASADO | R6: SI | S6: 1 | T6: 43297 | U6: 43282 | V6: 8.24 | W6: SIN DATO | Y6: OPERATIVO | Z6: SALUD HORISOES | AA6: POPAYAN | AB6: POPAYAN | AC6: INDEFINIDO | AD6: ACTIVO
A7: 45538319 | B7: F | C7: SINDIR DELLANIR NAIZIR BELTRAN | D7: GERENCIA ADMINISTRATIVA Y FINANCIERA | E7: dellanir.naizir@saludhorisoes.org | F7: GERENCIA | G7: oscar.vivas@saludhorisoes.org | H7: 3105268513 | I7: CAMPOARAGON CASA 8 | J7: deyanaizir24@hotmail.com | K7: OSCAR VIVAS | L7: ARMENIA | M7: 30126 | N7: 36706 | O7: CARTAGENA | P7: AB+ | Q7: CASADO | R7: SI | S7: 3 | T7: 43466 | U7: 43466 | V7: 7.78 | W7: SIN DATO | Y7: ADMINISTRATIVA | Z7: SALUD HORISOES | AA7: ARMENIA | AB7: NACIONAL | AC7: INDEFINIDO | AD7: ACTIVO
A8: 10290464 | B8: M | C8: CRISTIAN FERNANDO ORTEGA VASQUEZ | D8: AUDITOR MEDICO | E8: cristian.ortega@saludhorisoes.org | F8: DIRECCION SOCIOSANITARIA | G8: monica.barcasnegras@saludhorisoes.org, evelin.ortega@saludhorisoes.org | H8: 3116995062 | I8: CARRERA 19 N° 7 B - 12 POPAYÁN | J8: crisfeorva@gmail.com | K8: EVELIN ORTEGA | L8: POPAYAN | M8: 29606 | N8: 29606 | O8: POPAYAN | P8: O+ | Q8: UNION LIBRE | R8: SI | S8: 2 | T8: 43537 | U8: 43525 | V8: 7.59 | W8: SIN DATO | Y8: ADMINISTRATIVA | Z8: SALUD HORISOES | AA8: POPAYAN | AB8: NACIONAL | AC8: PRESTACION DE SERVICIOS | AD8: ACTIVO
A9: 1102812141 | B9: F | C9: MELISSA PAOLA CHICA BELEÑO | D9: DIRECCION DE AGENDAMIENTO Y DEMANDA INDUCIDA | E9: melissa.chica@saludhorisoes.org | F9: DIRECCION DE AGENDAMIENTO Y DEMANDA INDUCIDA | G9: melisa.chica@saludhorisoes.org | H9: 3013715224 | I9: CALLE 78n #9 - 126 TORRES DE MILANO | J9: melipao13@hotmail.com | K9: OSCAR VIVAS | L9: ARMENIA | M9: 32094 | N9: 38680 | O9: SINCELEJO | P9: B+ | Q9: CASADO | R9: SI | S9: 1 | T9: 44166 | U9: 44166 | V9: 5.86 | W9: SIN DATO | Y9: OPERATIVO | Z9: SALUD HORISOES | AA9: ARMENIA | AB9: NACIONAL | AC9: INDEFINIDO | AD9: ACTIVO
A10: 1061791075 | B10: M | C10: CARLOS EDUARDO MUÑOZ SENDOYA | D10: DIRECCION COMERCIAL | E10: carlos.munoz@saludhorisoes.org | F10: COMERCIAL | G10: oscar.vivas@saludhorisoes.org | H10: 3104754537 | I10: CRA 6 # 41N-135 TERRAZAS DEL CAMPESTRE APTO 401C | J10: carlosedms5@gmail.com | K10: OSCAR VIVAS | L10: BOGOTA | M10: 35222 | N10: 41801 | O10: POPAYAN | P10: O+ | Q10: SOLTERO | R10: NO | S10: 0 | T10: 44287 | U10: 44287 | V10: 5.53 | W10: SIN DATO | Y10: ADMINISTRATIVA | Z10: SALUD HORISOES | AA10: BOGOTA | AB10: NACIONAL | AC10: INDEFINIDO | AD10: ACTIVO
A11: 1061748921 | B11: M | C11: YONATAN JULIAN CARVAJAL ORTIZ | D11: DIRECCION TORRE DE CONTROL | E11: yonatan.carvajal@saludhorisoes.org | F11: INFORMACION Y GESTION DEL RIESGO EN SALUD | G11: jorge sanchez@saludhorisoes.org | H11: 3105193403 | I11: CARRERA 15 # 10-59 APTO 305 B/ EL ACHIRAL | J11: juliancarvajal14@gmail.com | K11: OSCAR VIVAS | L11: ARMENIA | M11: 33781 | N11: 40358 | O11: POPAYAN | P11: O+ | Q11: SOLTERO | R11: NO | S11: 0 | T11: 44516 | U11: 44501 | V11: 4.90 | W11: SIN DATO | X11: 46203 | Y11: ADMINISTRATIVA | Z11: SALUD HORISOES | AA11: ARMENIA | AB11: NACIONAL | AC11: INDEFINIDO | AD11: INACTIVO
A12: 1061816592 | B12: M | C12: MARLON ALEJANDRO MAYORQUIN CRUZ | D12: DIRECCION DE TICS | E12: alejandro.mayorquin@saludhorisoes.org | F12: RECURSOS TICS | G12: dellanir.naizir@saludhorisoes.org | H12: 3104875746 | I12: CALLE 2 E # 57 C - 43 LOMAS DE GRANADA | J12: macmdf@gmail.com | K12: DELLANIR NAIZIR | L12: POPAYAN | M12: 36245 | N12: 42821 | O12: POPAYAN | P12: O+ | Q12: SOLTERO | R12: NO | S12: 0 | T12: 44580 | U12: 44562 | V12: 4.73 | W12: SIN DATO | Y12: ADMINISTRATIVA | Z12: SALUD HORISOES | AA12: POPAYAN | AB12: NACIONAL | AC12: INDEFINIDO | AD12: ACTIVO
A13: 10305907 | B13: M | C13: JULIAN ANDRES MUÑOZ QUINAYAS | D13: AUXILIAR OPERATIVO UNIDAD MOVIL | E13: julian.munoz@saludhorisoes.org | F13: DIRECCION SOCIOSANITARIA | G13: maria.estrada@saludhorisoes.org | H13: 3147585118 | I13: CALLE 7A # 13 - 23 | J13: julianandmunos@unicauca.edu.co | K13: MARIA DANIELA ESTRADA | L13: POPAYAN | M13: 30628 | N13: 37751 | O13: POPAYAN | P13: O+ | Q13: CASADO | R13: SI | S13: 3 | T13: 44973 | U13: 44958 | V13: 3.65 | W13: SIN DATO | X13: 46279 | Y13: OPERATIVO | Z13: SALUD HORISOES | AA13: UNIDAD MOVIL | AB13: UNIDAD MOVIL | AC13: INDEFINIDO | AD13: INACTIVO
A14: 30338659 | B14: F | C14: LINA MARCELA ARANGO CIFUENTES | D14: LIDER REGIONAL | E14: lina.arango@saludhorisoes.org | F14: DIRECCION SOCIOSANITARIA | G14: jorge.sanchez@saludhorisoes.org, evelin.ortega@saludhorisoes.org | H14: 3182164837 | I14: CRA 15 # 4B-31 MIRADOR DE LA FRANCIA | J14: limaarci@hotmail.com | K14: LINA ARANGO | L14: MANIZALES | M14: 27833 | N14: 34638 | O14: MANIZALES | P14: A+ | Q14: SOLTERO | R14: SI | S14: 1 | T14: 45231 | U14: 45231 | V14: 2.95 | W14: 45290 | X14: 46227 | Y14: ASISTENCIAL | Z14: CONVENIO HORIZONTE | AA14: MANIZALES | AB14: MANIZALES | AC14: INDEFINIDO | AD14: INACTIVO
A15: 30328380 | B15: F | C15: SANDRA LILIANA ZAPATA HERRERA | D15: AUXILIAR SERVICIOS GENERALES | E15: sandra.zapata@saludhorisoes.org | F15: RECURSOS FISICOS | G15: lisa.castano@saludhorisoes.org | H15: 3234243443 | I15: Calle 58 F1 N 9B - 17, Localidad Cumbre en Manizales | J15: sandrazapatapepe@gmail.com | K15: LINA ARANGO | L15: MANIZALES | M15: 25930 | N15: 33550 | O15: MANIZALES | P15: O+ | Q15: CASADA | R15: SI | S15: 2 | T15: 45244 | U15: 45231 | V15: 2.91 | W15: SIN DATO | Y15: ADMINISTRATIVA | Z15: CONVENIO HORIZONTE | AA15: MANIZALES | AB15: MANIZALES | AC15: INDEFINIDO | AD15: ACTIVO
A16: 1053818618 | B16: F | C16: VIVIANA ECHEVERRI ROJAS | D16: AUXILIAR FACTURACION | E16: viviana.echeverri@saludhorisoes.org | F16: RECURSOS FINANCIEROS | G16: andres.suarez@saludhorisoes.org | H16: 3122374626 | I16: Calle 5 # 15 A 15 B/ La Pradera en Manizales | J16: vivianao09@hotmail.com | K16: JUAN MORALES | L16: MANIZALES | M16: 33743 | N16: 40319 | O16: MANIZALES | P16: O+ | Q16: SOLTERO | R16: NO | S16: 0 | T16: 45244 | U16: 45231 | V16: 2.91 | W16: SIN DATO | Y16: OPERATIVO | Z16: SALUD HORISOES | AA16: MANIZALES | AB16: MANIZALES | AC16: INDEFINIDO | AD16: ACTIVO
A17: 76325636 | B17: M | C17: RICARDO AARON PERAFAN MOSQUERA | D17: CONDUCTOR UNIDAD MOVIL | E17: ricardo.perafan@saludhorisoes.org | F17: RECURSOS FISICOS | G17: lisa.castano@saludhorisoes.org | H17: 3207224795 | I17: Carrera 38 # 15-25 BARRIO LAS PALMAS | J17: ripe0203@gmail.com | K17: LISA CASTAÑO | L17: POPAYAN | M17: 28186 | N17: 34792 | O17: POPAYAN | P17: O+ | Q17: UNION LIBRE | R17: SI | S17: 2 | T17: 45244 | U17: 45231 | V17: 2.91 | W17: SIN DATO | Y17: OPERATIVO | Z17: SALUD HORISOES | AA17: UNIDAD MOVIL | AB17: UNIDAD MOVIL | AC17: INDEFINIDO | AD17: ACTIVO
A18: 1053857243 | B18: F | C18: DANIELA VILLEGAS MARTINEZ | D18: PSICOLOGA | E18: daniela.villegas@saludhorisoes.org | F18: DIRECCION SOCIOSANITARIA | G18: monica.barcasnegras@saludhorisoes.org, evelin.ortega@saludhorisoes.org | H18: 3043941477 | I18: CRA 43 # 66-74 | J18: daniville1997@hotmail.com | K18: EVELIN ORTEGA | L18: MANIZALES | M18: 35573 | N18: 42151 | O18: MANIZALES | P18: O+ | Q18: SOLTERO | R18: NO | S18: 0 | T18: 45280 | U18: 45261 | V18: 2.81 | W18: SIN DATO | X18: 46253 | Y18: ASISTENCIAL | Z18: CONVENIO HORIZONTE | AA18: MANIZALES | AB18: MANIZALES | AC18: PRESTACION DE SERVICIOS | AD18: INACTIVO
A19: 76343027 | B19: M | C19: HAROL MAURICIO MUÑOZ CHAMORRO | D19: DISEÑO GRAFICO | E19: harol.munoz@saludhorisoes.org | F19: CULTURA, EDUCACION Y COMUNICACION | G19: dellanir.naizir@saludhorisoes.org | H19: 3128932132 | I19: Carrera 13 #16-55 | J19: harolmauricio8400@gmail.com | K19: DELLANIR NAIZIR | L19: POPAYAN | M19: 30982 | N19: 37735 | O19: TIMBIO | P19: O+ | Q19: SOLTERO | R19: NO | S19: 0 | T19: 45292 | U19: 45292 | V19: 2.78 | W19: 45325 | Y19: ADMINISTRATIVA | Z19: SALUD HORISOES | AA19: POPAYAN | AB19: NACIONAL | AC19: PRESTACION DE SERVICIOS | AD19: ACTIVO
A20: 1060879740 | B20: M | C20: JOSE RAFAEL CHAUX | D20: COORDINACION DE INFORMACION EXTRAMURAL | E20: rafael.chaux@saludhorisoes.org | F20: DIRECCION SOCIOSANITARIA | G20: jorge.sanchez@saludhorisoes.org | H20: 3233113436 | I20: MANZANA 25 CASA 10 LA PATRIA | J20: josecchauxpersonal@gmail.com | K20: MONICA BARCASNEGRAS | L20: ARMENIA | M20: 35806 | N20: 42381 | O20: EL TAMBO | P20: B+ | Q20: SOLTERO | R20: NO | S20: 0 | T20: 45293 | U20: 45292 | V20: 2.78 | W20: 45352 | X20: 46211 | Y20: OPERATIVO | Z20: SALUD HORISOES | AA20: ARMENIA | AB20: NACIONAL | AC20: INDEFINIDO | AD20: INACTIVO
A21: 1082972156 | B21: F | C21: ALEXANDRA JULIETH CANTILLO RAMOS | D21: PROFESIONAL TALENTO HUMANO | E21: alexandra.cantillo@saludhorisoes.org | F21: RECURSOS HUMANOS | G21: diego.burgos@saludhorisoes.org | H21: 3228953880 | I21: MANZANA A CASA 9 BARRIO MONTE CARLO | J21: cantillo133@gmail.com | K21: DIEGO BURGOS | L21: CALARCA | M21: 34205 | N21: 40794 | O21: SANTA MARTA | P21: A+ | Q21: UNION LIBRE | R21: NO | S21: 0 | T21: 45294 | U21: 45292 | V21: 2.77 | W21: 45353 | Y21: ADMINISTRATIVA | Z21: SALUD HORISOES | AA21: ARMENIA | AB21: NACIONAL | AC21: INDEFINIDO | AD21: ACTIVO
A22: 34316697 | B22: F | C22: ANGELA YOLIMA GUAMANGA SAMBONI | D22: TECNICO DE IMAGENES DIAGNOSTICAS | E22: angela.guamanga@saludhorisoes.org | F22: DIRECCION SOCIOSANITARIA | G22: maria.estrada@saludhorisoes.org | H22: 3154709402 | I22: CARRERA 8H # 66BN - 39 | J22: angelaguamanga300182@gmail.com | K22: MARIA DANIELA ESTRADA | L22: POPAYAN | M22: 29981 | N22: 36648 | O22: POPAYAN | P22: O+ | Q22: SOLTERO | R22: SI | S22: 2 | T22: 45323 | U22: 45323 | V22: 2.69 | W22: 45382 | Y22: ASISTENCIAL | Z22: CONVENIO HORIZONTE | AA22: UNIDAD MOVIL | AB22: UNIDAD MOVIL | AC22: INDEFINIDO | AD22: ACTIVO
A23: 1004799714 | B23: F | C23: MARIA JOSE COBALEDA AGUIRRE | D23: TECNICO ADMINISTRATIVO UNIDAD MOVIL | E23: maria.cobaleda@saludhorisoes.org | F23: DIRECCION SOCIOSANITARIA | G23: jorge.sanchez@saludhorisoes.org, evelin.ortega@saludhorisoes.org | H23: 3138084317 | I23: CARRERA 23E # 3-66 B/ MODELO | J23: mcobaledaaguirre@gmail.com | K23: MARIA DANIELA ESTRADA | L23: ARMENIA | M23: 37105 | N23: 43753 | O23: ARMENIA | P23: A+ | Q23: SOLTERO | R23: NO | S23: 0 | T23: 45323 | U23: 45323 | V23: 2.69 | W23: 45382 | X23: 46055 | Y23: ADMINISTRATIVA | Z23: SALUD HORISOES | AA23: ARMENIA | AB23: NACIONAL | AC23: INDEFINIDO | AD23: INACTIVO
A24: 24587269 | B24: F | C24: YENNYFER GUIZA ALVAREZ | D24: TECNICO FACTURACION | E24: yennyfer.guiza@saludhorisoes.org | F24: RECURSOS FINANCIEROS | G24: andres.suarez@saludhorisoes.org | H24: 3224922719 | I24: CARRERA 32 # 19-40 B/ LA ESPERANZA | J24: yeis2024@gmail.com | K24: JUAN MORALES | L24: ARMENIA | M24: 31098 | N24: 37676 | O24: CALARCA | P24: A+ | Q24: UNION LIBRE | R24: SI | S24: 4 | T24: 45348 | U24: 45323 | V24: 2.62 | W24: 45407 | Y24: ADMINISTRATIVA | Z24: SALUD HORISOES | AA24: ARMENIA | AB24: NACIONAL | AC24: INDEFINIDO | AD24: ACTIVO
A25: 1006848706 | B25: F | C25: NATALIA MARITZA HERNANDEZ CABRERA | D25: AUXILIAR TOMA DE MUESTRAS UNIDAD MOVIL | E25: natalia.hernandez@saludhorisoes.org | F25: DIRECCION SOCIOSANITARIA | G25: maria.estrada@saludhorisoes.org | H25: 3113247105 | I25: CARRERA 6 # 26B N19 B/ LOS HOYOS | J25: nataliah-cabrera@hotmail.com | K25: MARIA DANIELA ESTRADA | L25: POPAYAN | M25: 36684 | N25: 43263 | O25: ORITO | P25: O+ | Q25: SOLTERA | R25: NO | S25: 0 | T25: 45350 | U25: 45323 | V25: 2.62 | W25: 45409 | Y25: ASISTENCIAL | Z25: CONVENIO HORIZONTE | AA25: UNIDAD MOVIL | AB25: UNIDAD MOVIL | AC25: INDEFINIDO | AD25: ACTIVO
A26: 1094963164 | B26: F | C26: GLORIA ALEJANDRA MARULANDA MELCHOR | D26: HIGIENISTA ORAL | E26: gloria.marulanda@saludhorisoes.org | F26: DIRECCION SOCIOSANITARIA | G26: jorge.sanchez@saludhorisoes.org, evelin.ortega@saludhorisoes.org | H26: 3104423727 | I26: MANZANA G # 26 PISO 1 | J26: alejandramarulanda730@gmail.com | K26: EVELIN ORTEGA | L26: ARMENIA | M26: 35621 | N26: 42214 | O26: ARMENIA | P26: A+ | Q26: SOLTERA | R26: NO | S26: 0 | T26: 45350 | U26: 45323 | V26: 2.62 | W26: 45409 | Y26: ASISTENCIAL | Z26: CONVENIO HORIZONTE | AA26: ARMENIA | AB26: ARMENIA | AC26: INDEFINIDO | AD26: ACTIVO
A27: 1193271704 | B27: F | C27: DIANA MARCELA CHILAMA GOMEZ | D27: AUXILIAR SERVICIOS GENERALES | E27: diana.chilama@saludhorisoes.org | F27: RECURSOS FISICOS | G27: lisa.castano@saludhorisoes.org | H27: 3013099499 | I27: CARRERA 11 NORTE # 18-72 | J27: dmchg20@gmail.com | K27: EVELIN ORTEGA | L27: ARMENIA | M27: 37192 | N27: 43805 | O27: CONTADERO | P27: O+ | Q27: SOLTERA | R27: NO | S27: 0 | T27: 45355 | U27: 45352 | V27: 2.61 | W27: 45415 | X27: 46095 | Y27: ADMINISTRATIVA | Z27: CONVENIO HORIZONTE | AA27: ARMENIA | AB27: ARMENIA | AC27: INDEFINIDO | AD27: INACTIVO
A28: 1061685871 | B28: F | C28: ADRIANA EUGENIA MUÑOZ PIZO | D28: PROFESIONAL DE ANALISIS DE INFORMACION | E28: adriana.munoz@saludhorisoes.org | F28: INFORMACION Y GESTION DEL RIESGO EN SALUD | G28: andres.ordones@saludhorisoes.org | H28: 3207516189 | I28: CARRERA 24A # 15-23 | J28: adrianaeugeniamunozpizo1061@gmail.com | K28: ANDRES ORDOÑEZ | L28: POPAYAN | M28: 31268 | N28: 38089 | O28: POPAYAN | P28: O+ | Q28: SOLTERO | R28: NO | S28: 0 | T28: 45371 | U28: 45352 | V28: 2.56 | W28: 45431 | Y28: OPERATIVO | Z28: SALUD HORISOES | AA28: POPAYAN | AB28: POPAYAN | AC28: INDEFINIDO | AD28: ACTIVO
A29: 1095550962 | B29: F | C29: MARIA JOSE MATALLANA GUIZA | D29: AUXILIAR DE GESTION DEL RIESGO | E29: maria.matallana@saludhorisoes.org | F29: DIRECCION SOCIOSANITARIA | G29: maria.estrada@saludhorisoes.org | H29: 3218824175 | I29: CARRERA 32A # 19-40 B/ LA ESPERANZA | J29: mariajosematallana61@gmail.com | K29: MARIA DANIELA ESTRADA | L29: ARMENIA | M29: 38617 | N29: 45237 | O29: CALARCA | P29: A+ | Q29: SOLTERO | R29: NO | S29: 0 | T29: 45390 | U29: 45383 | V29: 2.51 | W29: 45450 | Y29: OPERATIVO | Z29: SALUD HORISOES | AA29: ARMENIA | AB29: NACIONAL | AC29: INDEFINIDO | AD29: ACTIVO
A30: 18417654 | B30: M | C30: YVER MOLINA GIL | D30: CONDUCTOR UNIDAD MOVIL | E30: yver.molina@saludhorisoes.org | F30: RECURSOS FISICOS | G30: lisa.castano@saludhorisoes.org | H30: 3117672528 | I30: MANZANA O CASA 21 VILLA JERUSALEN | J30: molinagilyver@gmail.com | K30: LISA CASTAÑO | L30: ARMENIA | M30: 28574 | N30: 35279 | O30: MONTENEGRO | P30: O+ | Q30: SOLTERO | R30: NO | S30: 0 | T30: 45390 | U30: 45383 | V30: 2.51 | W30: 45433 | Y30: OPERATIVO | Z30: SALUD HORISOES | AA30: UNIDAD MOVIL | AB30: UNIDAD MOVIL | AC30: INDEFINIDO | AD30: ACTIVO
A31: 15373819 | B31: M | C31: ARLEY VICENTE FORERO TOVAR | D31: TECNICO DE CUENTAS MEDICAS | E31: arley.forero@saludhorisoes.org | F31: AUDITORIA | G31: paulo.navarro@saludhorisoes.org | H31: 3222113049 | I31: CALLE 32 # 23-35 APTO 401 B/LAS CAMELIAS | J31: arleyforero@hotmail.com | K31: PAULO NAVARRO | L31: ARMENIA | M31: 31007 | N31: 37613 | O31: MEDELLIN | P31: B+ | Q31: SOLTERO | R31: NO | S31: 0 | T31: 45400 | U31: 45383 | V31: 2.48 | W31: 45452 | Y31: ADMINISTRATIVA | Z31: SALUD HORISOES | AA31: ARMENIA | AB31: NACIONAL | AC31: INDEFINIDO | AD31: ACTIVO
A32: 1094961794 | B32: F | C32: MARIA FERNANDA PESCADOR LORA | D32: PROFESIONAL CONTABLE | E32: maria.pescador@saludhorisoes.org | F32: RECURSOS FINANCIEROS | G32: andres.suarez@saludhorisoes.org | H32: 3137207949 | I32: MANZANA 1 CASA 4 GUADUALES DE LA VILLA | J32: mafe-9704@outlook.com | K32: ANA MARIA HINCAPIE | L32: ARMENIA | M32: 35554 | N32: 42131 | O32: ARMENIA | P32: O+ | Q32: SOLTERO | R32: NO | S32: 0 | T32: 45404 | U32: 45383 | V32: 2.47 | W32: 45464 | Y32: ADMINISTRATIVA | Z32: SALUD HORISOES | AA32: ARMENIA | AB32: NACIONAL | AC32: INDEFINIDO | AD32: ACTIVO
A33: 1098313885 | B33: M | C33: JUAN DIEGO MUÑETON BRITO | D33: PROFESIONAL DE GESTION POBLACIONAL | E33: juan.muneton@saludhorisoes.org | F33: INFORMACION Y GESTION DEL RIESGO EN SALUD | G33: andres.ordones@saludhorisoes.org | H33: 3219130670 | I33: CALLE 42 # 21-27 B/ CACIQUE | J33: mikasa6662@gmail.com | K33: MARIA DANIELA ESTRADA | L33: ARMENIA | M33: 36540 | N33: 43117 | O33: CIRCASIA | P33: O+ | Q33: UNION LIBRE | R33: NO | S33: 0 | T33: 45414 | U33: 45413 | V33: 2.44 | W33: 45455 | Y33: OPERATIVO | Z33: SALUD HORISOES | AA33: ARMENIA | AB33: NACIONAL | AC33: INDEFINIDO | AD33: ACTIVO
A34: 1094951546 | B34: F | C34: YULY ALEJANDRA VILLAMIL CAMARGO | D34: PROFESIONAL DE SEGURIDAD Y SALUD EN EL TRABAJO | E34: alejandra.villamil@saludhorisoes.org | F34: RECURSOS HUMANOS | G34: diego.burgos@saludhorisoes.org | H34: 3183758625 | I34: MANZANA D CASA 1 B/ QUINTAS DE LA MARINA | J34: yavillamilca@gmail.com | K34: DIEGO BURGOS | L34: ARMENIA | M34: 34961 | N34: 41537 | O34: ARMENIA | P34: O+ | Q34: CASADA | R34: SI | S34: 1 | T34: 45418 | U34: 45413 | V34: 2.43 | W34: 45478 | Y34: ADMINISTRATIVA | Z34: SALUD HORISOES | AA34: ARMENIA | AB34: NACIONAL | AC34: INDEFINIDO | AD34: ACTIVO
A35: 1061815009 | B35: F | C35: ADA MARY MANZANO QUIÑONES | D35: AUXILIAR AGENDAMIENTO | E35: ada.manzano@saludhorisoes.org | F35: DIRECCION DE AGENDAMIENTO Y DEMANDA INDUCIDA | G35: diana.fernandez@saludhorisoes.org, melissa.chica@saludhorisoes.org | H35: 3185550548 | I35: CARRERA 10 # 27-10 B/ LOMA DE LA VIRGEN | J35: adamanzzano1915@hotmail.com | K35: MELISSA CHICA, DIANA FERNANDEZ | L35: POPAYAN | M35: 36136 | N35: 42748 | O35: POPAYAN | P35: A+ | Q35: SOLTERO | R35: SI | S35: 1 | T35: 45426 | U35: 45413 | V35: 2.41 | W35: 45456 | Y35: OPERATIVO | Z35: SALUD HORISOES | AA35: POPAYAN | AB35: POPAYAN | AC35: INDEFINIDO | AD35: ACTIVO
A36: 1061817672 | B36: F | C36: LEICY TATIANA PERAFAN SALAZAR | D36: AUXILIAR SIAU | E36: leicy.perafan@ipshorisoes.org | F36: DIRECCION SOCIOSANITARIA | G36: evelin.ortega@saludhorisoes.org | H36: 3234677950 | I36: CARRERA 39 # 6B - 71 B/COLOMBIA II ETAPA | J36: tatianaperafans21@gmail.com | K36: ANDREA OROZCO | L36: POPAYAN | M36: 36271 | N36: 42872 | O36: POPAYAN | P36: O+ | Q36: SOLTERA | R36: NO | S36: 0 | T36: 45427 | U36: 45413 | V36: 2.41 | W36: 45458 | X36: 46195 | Y36: ASISTENCIAL | Z36: CONVENIO HORIZONTE | AA36: POPAYAN | AB36: POPAYAN | AC36: INDEFINIDO | AD36: INACTIVO
A37: 1089481650 | B37: F | C37: JOHANA DAISURY MENESES VALDES | D37: MEDICO GENERAL | E37: johana.meneses@saludhorisoes.org | F37: DIRECCION SOCIOSANITARIA | G37: evelin.ortega@saludhorisoes.org | H37: 3233214564 | I37: CALLE 8N # 8-05 BARRIO PRADOS DEL NORTE | J37: joha535@hotmail.com | K37: EVELIN ORTEGA | L37: POPAYAN | M37: 32918 | N37: 39519 | O37: LA UNION | P37: B+ | Q37: UNION LIBRE | R37: SI | S37: 1 | T37: 45428 | U37: 45413 | V37: 2.41 | W37: 45445 | Y37: ASISTENCIAL | Z37: CONVENIO HORIZONTE | AA37: POPAYAN | AB37: POPAYAN | AC37: INDEFINIDO | AD37: ACTIVO
A38: 34562913 | B38: F | C38: LUZ ELENA ZEMANATE NARVAEZ | D38: AUXILIAR TOMA DE MUESTRAS DE LABORATORIO | E38: luz.zemanate@saludhorisoes.org | F38: DIRECCION SOCIOSANITARIA | G38: evelin.ortega@saludhorisoes.org | H38: 3117884359 | I38: CARRERA 13 # 2-46 BARRIO CADILLAL | J38: zemanatenarvaezluzelena@gmail.com | K38: ANDREA OROZCO | L38: POPAYAN | M38: 25467 | N38: 33417 | O38: POPAYAN | P38: O+ | Q38: UNION LIBRE | R38: SI | S38: 1 | T38: 45432 | U38: 45413 | V38: 2.39 | W38: 45449 | Y38: ASISTENCIAL | Z38: CONVENIO HORIZONTE | AA38: POPAYAN | AB38: POPAYAN | AC38: INDEFINIDO | AD38: ACTIVO
A39: 25278950 | B39: F | C39: JENNY PATRICIA LOPEZ RIVERA | D39: AUXILIAR SERVICIOS GENERALES | E39: jenny.rivera@saludhorisoes.org | F39: RECURSOS FISICOS | G39: lisa.castano@saludhorisoes.org | H39: 3137868948 | I39: TOMACIPRIANO ALTO MANZANA16 # 16-04 | J39: yennyrlopez09@gmail.com | K39: LISA CASTAÑO | L39: POPAYAN | M39: 28558 | N39: 35502 | O39: POPAYAN | P39: B+ | Q39: UNION LIBRE | R39: SI | S39: 2 | T39: 45444 | U39: 45444 | V39: 2.36 | W39: 45031 | Y39: ADMINISTRATIVA | Z39: CONVENIO HORIZONTE | AA39: POPAYAN | AB39: POPAYAN | AC39: INDEFINIDO | AD39: ACTIVO
A40: 34569893 | B40: F | C40: AIDA ALICIA AVIRAMA MAPALLO | D40: ORIENTADORA | E40: aida.avirama@ipshorisoes.org | F40: DIRECCION SOCIOSANITARIA | G40: evelin.ortega@saludhorisoes.org | H40: 3148252670 | I40: calle 25 B N. 7°08 BARRIO NUEVO JAPON | J40: sdaa2596@hotmail.com | K40: ANDREA OROZCO | L40: POPAYAN | M40: 27233 | N40: 34264 | O40: POPAYAN | P40: O+ | Q40: CASADO | R40: SI | S40: 1 | T40: 45444 | U40: 45444 | V40: 2.36 | W40: 45504 | Y40: ASISTENCIAL | Z40: CONVENIO HORIZONTE | AA40: POPAYAN | AB40: POPAYAN | AC40: INDEFINIDO | AD40: ACTIVO
...
